<sdf version='1.7'>
  <world name='default'>
    <light name='sun' type='directional'>
      <cast_shadows>1</cast_shadows>
      <pose>0 0 10 0 -0 0</pose>
      <diffuse>0.8 0.8 0.8 1</diffuse>
      <specular>0.2 0.2 0.2 1</specular>
      <attenuation>
        <range>1000</range>
        <constant>0.9</constant>
        <linear>0.01</linear>
        <quadratic>0.001</quadratic>
      </attenuation>
      <direction>-0.5 0.1 -0.9</direction>
      <spot>
        <inner_angle>0</inner_angle>
        <outer_angle>0</outer_angle>
        <falloff>0</falloff>
      </spot>
    </light>
    <model name='ground_plane'>
      <static>1</static>
      <link name='link'>
        <collision name='collision'>
          <geometry>
            <plane>
              <normal>0 0 1</normal>
              <size>100 100</size>
            </plane>
          </geometry>
          <surface>
            <contact>
              <collide_bitmask>65535</collide_bitmask>
              <ode/>
            </contact>
            <friction>
              <ode>
                <mu>100</mu>
                <mu2>50</mu2>
              </ode>
              <torsional>
                <ode/>
              </torsional>
            </friction>
            <bounce/>
          </surface>
          <max_contacts>10</max_contacts>
        </collision>
        <visual name='visual'>
          <cast_shadows>0</cast_shadows>
          <geometry>
            <plane>
              <normal>0 0 1</normal>
              <size>100 100</size>
            </plane>
          </geometry>
          <material>
            <script>
              <uri>file://media/materials/scripts/gazebo.material</uri>
              <name>Gazebo/Grey</name>
            </script>
          </material>
        </visual>
        <self_collide>0</self_collide>
        <enable_wind>0</enable_wind>
        <kinematic>0</kinematic>
      </link>
    </model>
    <gravity>0 0 -9.8</gravity>
    <magnetic_field>6e-06 2.3e-05 -4.2e-05</magnetic_field>
    <atmosphere type='adiabatic'/>
    <physics type='ode'>
      <max_step_size>0.001</max_step_size>
      <real_time_factor>1</real_time_factor>
      <real_time_update_rate>1000</real_time_update_rate>
    </physics>
    <scene>
      <ambient>0.4 0.4 0.4 1</ambient>
      <background>0.7 0.7 0.7 1</background>
      <shadows>1</shadows>
    </scene>
    <wind/>
    <spherical_coordinates>
      <surface_model>EARTH_WGS84</surface_model>
      <latitude_deg>0</latitude_deg>
      <longitude_deg>0</longitude_deg>
      <elevation>0</elevation>
      <heading_deg>0</heading_deg>
    </spherical_coordinates>
    <model name='first_2015_trash_can'>
      <link name='link'>
        <inertial>
          <pose>0 0 0.3683 0 -0 0</pose>
          <mass>4.83076</mass>
          <inertia>
            <ixx>0.281534</ixx>
            <ixy>0</ixy>
            <ixz>0</ixz>
            <iyy>0.281534</iyy>
            <iyz>0</iyz>
            <izz>0.126223</izz>
          </inertia>
        </inertial>
        <visual name='visual'>
          <geometry>
            <mesh>
              <uri>model://first_2015_trash_can/meshes/trash_can.dae</uri>
            </mesh>
          </geometry>
        </visual>
        <collision name='collision'>
          <geometry>
            <mesh>
              <uri>model://first_2015_trash_can/meshes/trash_can.dae</uri>
            </mesh>
          </geometry>
          <max_contacts>10</max_contacts>
          <surface>
            <contact>
              <ode/>
            </contact>
            <bounce/>
            <friction>
              <torsional>
                <ode/>
              </torsional>
              <ode/>
            </friction>
          </surface>
        </collision>
        <self_collide>0</self_collide>
        <enable_wind>0</enable_wind>
        <kinematic>0</kinematic>
      </link>
      <pose>-2.36461 0.298385 0 0 -0 0</pose>
    </model>
    <model name='first_2015_trash_can_0'>
      <link name='link'>
        <inertial>
          <pose>0 0 0.3683 0 -0 0</pose>
          <mass>4.83076</mass>
          <inertia>
            <ixx>0.281534</ixx>
            <ixy>0</ixy>
            <ixz>0</ixz>
            <iyy>0.281534</iyy>
            <iyz>0</iyz>
            <izz>0.126223</izz>
          </inertia>
        </inertial>
        <visual name='visual'>
          <geometry>
            <mesh>
              <uri>model://first_2015_trash_can/meshes/trash_can.dae</uri>
            </mesh>
          </geometry>
        </visual>
        <collision name='collision'>
          <geometry>
            <mesh>
              <uri>model://first_2015_trash_can/meshes/trash_can.dae</uri>
            </mesh>
          </geometry>
          <max_contacts>10</max_contacts>
          <surface>
            <contact>
              <ode/>
            </contact>
            <bounce/>
            <friction>
              <torsional>
                <ode/>
              </torsional>
              <ode/>
            </friction>
          </surface>
        </collision>
        <self_collide>0</self_collide>
        <enable_wind>0</enable_wind>
        <kinematic>0</kinematic>
      </link>
      <pose>-2.32439 2.34435 0 0 -0 0</pose>
    </model>
    <model name='first_2015_trash_can_1'>
      <link name='link'>
        <inertial>
          <pose>0 0 0.3683 0 -0 0</pose>
          <mass>4.83076</mass>
          <inertia>
            <ixx>0.281534</ixx>
            <ixy>0</ixy>
            <ixz>0</ixz>
            <iyy>0.281534</iyy>
            <iyz>0</iyz>
            <izz>0.126223</izz>
          </inertia>
        </inertial>
        <visual name='visual'>
          <geometry>
            <mesh>
              <uri>model://first_2015_trash_can/meshes/trash_can.dae</uri>
            </mesh>
          </geometry>
        </visual>
        <collision name='collision'>
          <geometry>
            <mesh>
              <uri>model://first_2015_trash_can/meshes/trash_can.dae</uri>
            </mesh>
          </geometry>
          <max_contacts>10</max_contacts>
          <surface>
            <contact>
              <ode/>
            </contact>
            <bounce/>
            <friction>
              <torsional>
                <ode/>
              </torsional>
              <ode/>
            </friction>
          </surface>
        </collision>
        <self_collide>0</self_collide>
        <enable_wind>0</enable_wind>
        <kinematic>0</kinematic>
      </link>
      <pose>-2.31381 -0.49556 0 0 -0 0</pose>
    </model>
    <model name='grey_wall'>
      <static>1</static>
      <link name='link'>
        <pose>0 0 1.4 0 -0 0</pose>
        <collision name='collision'>
          <geometry>
            <box>
              <size>7.5 0.2 2.8</size>
            </box>
          </geometry>
          <max_contacts>10</max_contacts>
          <surface>
            <contact>
              <ode/>
            </contact>
            <bounce/>
            <friction>
              <torsional>
                <ode/>
              </torsional>
              <ode/>
            </friction>
          </surface>
        </collision>
        <visual name='visual'>
          <cast_shadows>0</cast_shadows>
          <geometry>
            <box>
              <size>7.5 0.2 2.8</size>
            </box>
          </geometry>
          <material>
            <script>
              <uri>model://grey_wall/materials/scripts</uri>
              <uri>model://grey_wall/materials/textures</uri>
              <name>vrc/grey_wall</name>
            </script>
          </material>
        </visual>
        <self_collide>0</self_collide>
        <enable_wind>0</enable_wind>
        <kinematic>0</kinematic>
      </link>
      <pose>-0.375864 4.47125 0 0 -0 0</pose>
    </model>
    <model name='grey_wall_0'>
      <static>1</static>
      <link name='link'>
        <pose>0 0 1.4 0 -0 0</pose>
        <collision name='collision'>
          <geometry>
            <box>
              <size>7.5 0.2 2.8</size>
            </box>
          </geometry>
          <max_contacts>10</max_contacts>
          <surface>
            <contact>
              <ode/>
            </contact>
            <bounce/>
            <friction>
              <torsional>
                <ode/>
              </torsional>
              <ode/>
            </friction>
          </surface>
        </collision>
        <visual name='visual'>
          <cast_shadows>0</cast_shadows>
          <geometry>
            <box>
              <size>7.5 0.2 2.8</size>
            </box>
          </geometry>
          <material>
            <script>
              <uri>model://grey_wall/materials/scripts</uri>
              <uri>model://grey_wall/materials/textures</uri>
              <name>vrc/grey_wall</name>
            </script>
          </material>
        </visual>
        <self_collide>0</self_collide>
        <enable_wind>0</enable_wind>
        <kinematic>0</kinematic>
      </link>
      <pose>-0.482636 -4.28038 0 0 -0 0</pose>
    </model>
    <model name='cart_model2'>
      <pose>3.17771 2.65555 0 0 -0 0</pose>
      <link name='base_link'>
        <pose>0 0 0 0 0 -1.5708</pose>
        <inertial>
          <pose>0 -0.5 0.5 0 -0 0</pose>
          <mass>30</mass>
          <inertia>
            <ixx>0.1</ixx>
            <ixy>0</ixy>
            <ixz>0</ixz>
            <iyy>0.1</iyy>
            <iyz>0</iyz>
            <izz>0.1</izz>
          </inertia>
        </inertial>
        <collision name='base_link_collision'>
          <pose>0 0 0 0 -0 0</pose>
          <geometry>
            <mesh>
              <scale>1 1 1</scale>
              <uri>/home/bambinojr/.ignition/fuel/fuel.ignitionrobotics.org/movai/models/cart_model_2/2/meshes/cart_base_collision.stl</uri>
            </mesh>
          </geometry>
          <max_contacts>5</max_contacts>
          <surface>
            <contact>
              <ode>
                <soft_cfm>1</soft_cfm>
                <soft_erp>0.4</soft_erp>
                <kp>1e+06</kp>
                <kd>1</kd>
                <min_depth>0.01</min_depth>
              </ode>
            </contact>
            <friction>
              <ode>
                <mu>1.16</mu>
                <mu2>1.16</mu2>
              </ode>
              <torsional>
                <ode/>
              </torsional>
            </friction>
            <bounce/>
          </surface>
        </collision>
        <visual name='base_link_visual'>
          <pose>0 0 0 0 -0 0</pose>
          <geometry>
            <mesh>
              <scale>1 1 1</scale>
              <uri>/home/bambinojr/.ignition/fuel/fuel.ignitionrobotics.org/movai/models/cart_model_2/2/meshes/cart_base.dae</uri>
              <submesh>
                <name>base_metal</name>
                <center>0</center>
              </submesh>
            </mesh>
          </geometry>
        </visual>
        <visual name='base_shelf_visual'>
          <pose>0 0 0 0 -0 0</pose>
          <geometry>
            <mesh>
              <scale>1 1 1</scale>
              <uri>/home/bambinojr/.ignition/fuel/fuel.ignitionrobotics.org/movai/models/cart_model_2/2/meshes/cart_base.dae</uri>
              <submesh>
                <name>base_shelf</name>
                <center>0</center>
              </submesh>
            </mesh>
          </geometry>
        </visual>
        <visual name='back_left_sup_visual'>
          <pose>-0.245 -1.005 0.05 0 -0 0</pose>
          <geometry>
            <mesh>
              <scale>1 1 1</scale>
              <uri>/home/bambinojr/.ignition/fuel/fuel.ignitionrobotics.org/movai/models/cart_model_2/2/meshes/sup_wheels.dae</uri>
            </mesh>
          </geometry>
        </visual>
        <visual name='back_right_sup_visual'>
          <pose>0.245 -1.005 0.05 0 -0 0</pose>
          <geometry>
            <mesh>
              <scale>1 1 1</scale>
              <uri>/home/bambinojr/.ignition/fuel/fuel.ignitionrobotics.org/movai/models/cart_model_2/2/meshes/sup_wheels.dae</uri>
            </mesh>
          </geometry>
        </visual>
        <visual name='tag_visual'>
          <pose>0 0 0 0 -0 0</pose>
          <geometry>
            <mesh>
              <scale>1 1 1</scale>
              <uri>/home/bambinojr/.ignition/fuel/fuel.ignitionrobotics.org/movai/models/cart_model_2/2/meshes/cart_base.dae</uri>
              <submesh>
                <name>tag</name>
                <center>0</center>
              </submesh>
            </mesh>
          </geometry>
          <material>
            <diffuse>1 1 1 1</diffuse>
            <specular>1 1 1 1</specular>
            <pbr>
              <metal>
                <albedo_map>meshes/cart_tag.png</albedo_map>
              </metal>
            </pbr>
          </material>
        </visual>
        <self_collide>0</self_collide>
        <enable_wind>0</enable_wind>
        <kinematic>0</kinematic>
      </link>
      <link name='back_left'>
        <pose>-1.04 -0.245 -0.05 0 -0 1.5708</pose>
        <inertial>
          <pose>0 0 0 3.14159 1.57079 3.14159</pose>
          <mass>0.01</mass>
          <inertia>
            <ixx>1.75e-05</ixx>
            <ixy>0</ixy>
            <ixz>0</ixz>
            <iyy>1.75e-05</iyy>
            <iyz>0</iyz>
            <izz>3.125e-05</izz>
          </inertia>
        </inertial>
        <collision name='back_left_collision'>
          <pose>0 0 0 3.14159 1.57079 3.14159</pose>
          <geometry>
            <cylinder>
              <length>0.03</length>
              <radius>0.06</radius>
            </cylinder>
          </geometry>
          <max_contacts>5</max_contacts>
          <surface>
            <contact>
              <ode>
                <soft_cfm>1</soft_cfm>
                <soft_erp>0.4</soft_erp>
                <kp>1e+06</kp>
                <kd>1</kd>
                <min_depth>0.01</min_depth>
              </ode>
            </contact>
            <friction>
              <ode>
                <mu>1.16</mu>
                <mu2>1.16</mu2>
              </ode>
              <torsional>
                <ode/>
              </torsional>
            </friction>
            <bounce/>
          </surface>
        </collision>
        <visual name='back_left_visual'>
          <pose>0 0 0 0 -0 0</pose>
          <geometry>
            <mesh>
              <scale>1 1 1</scale>
              <uri>/home/bambinojr/.ignition/fuel/fuel.ignitionrobotics.org/movai/models/cart_model_2/2/meshes/wheel.dae</uri>
            </mesh>
          </geometry>
        </visual>
        <self_collide>0</self_collide>
        <enable_wind>0</enable_wind>
        <kinematic>0</kinematic>
      </link>
      <joint name='back_left_joint' type='revolute'>
        <child>back_left</child>
        <parent>base_link</parent>
        <axis>
          <xyz>1 0 0</xyz>
          <dynamics>
            <friction>0.5</friction>
            <damping>0.0001</damping>
            <spring_reference>0</spring_reference>
            <spring_stiffness>0</spring_stiffness>
          </dynamics>
          <limit>
            <lower>-1e+16</lower>
            <upper>1e+16</upper>
          </limit>
        </axis>
      </joint>
      <link name='back_right'>
        <pose>-1.04 0.245 -0.05 0 -0 1.5708</pose>
        <inertial>
          <pose>0 0 0 3.14159 1.57079 3.14159</pose>
          <mass>0.01</mass>
          <inertia>
            <ixx>1.75e-05</ixx>
            <ixy>0</ixy>
            <ixz>0</ixz>
            <iyy>1.75e-05</iyy>
            <iyz>0</iyz>
            <izz>3.125e-05</izz>
          </inertia>
        </inertial>
        <collision name='back_right_collision'>
          <pose>0 0 0 3.14159 1.57079 3.14159</pose>
          <geometry>
            <cylinder>
              <length>0.03</length>
              <radius>0.06</radius>
            </cylinder>
          </geometry>
          <max_contacts>5</max_contacts>
          <surface>
            <contact>
              <ode>
                <soft_cfm>1</soft_cfm>
                <soft_erp>0.4</soft_erp>
                <kp>1e+06</kp>
                <kd>1</kd>
                <min_depth>0.01</min_depth>
              </ode>
            </contact>
            <friction>
              <ode>
                <mu>1.16</mu>
                <mu2>1.16</mu2>
              </ode>
              <torsional>
                <ode/>
              </torsional>
            </friction>
            <bounce/>
          </surface>
        </collision>
        <visual name='back_right_visual'>
          <pose>0 0 0 0 -0 0</pose>
          <geometry>
            <mesh>
              <scale>1 1 1</scale>
              <uri>/home/bambinojr/.ignition/fuel/fuel.ignitionrobotics.org/movai/models/cart_model_2/2/meshes/wheel.dae</uri>
            </mesh>
          </geometry>
        </visual>
        <self_collide>0</self_collide>
        <enable_wind>0</enable_wind>
        <kinematic>0</kinematic>
      </link>
      <joint name='back_right_joint' type='revolute'>
        <child>back_right</child>
        <parent>base_link</parent>
        <axis>
          <xyz>1 0 0</xyz>
          <dynamics>
            <friction>0.5</friction>
            <damping>0.0001</damping>
            <spring_reference>0</spring_reference>
            <spring_stiffness>0</spring_stiffness>
          </dynamics>
          <limit>
            <lower>-1e+16</lower>
            <upper>1e+16</upper>
          </limit>
        </axis>
      </joint>
      <link name='wheel_sup_front_left'>
        <pose>0 -0.245 0.05 0 -0 1.5708</pose>
        <inertial>
          <pose>0 0 0 0 -0 0</pose>
          <mass>0.01</mass>
          <inertia>
            <ixx>1.75e-05</ixx>
            <ixy>0</ixy>
            <ixz>0</ixz>
            <iyy>1.75e-05</iyy>
            <iyz>0</iyz>
            <izz>1.75e-05</izz>
          </inertia>
        </inertial>
        <visual name='wheel_sup_front_left_visual'>
          <pose>0 0 0 0 -0 -3.14159</pose>
          <geometry>
            <mesh>
              <scale>1 1 1</scale>
              <uri>/home/bambinojr/.ignition/fuel/fuel.ignitionrobotics.org/movai/models/cart_model_2/2/meshes/sup_wheels.dae</uri>
            </mesh>
          </geometry>
        </visual>
        <self_collide>0</self_collide>
        <enable_wind>0</enable_wind>
        <kinematic>0</kinematic>
      </link>
      <joint name='wheel_sup_front_left_joint' type='revolute'>
        <child>wheel_sup_front_left</child>
        <parent>base_link</parent>
        <axis>
          <xyz>0 0 1</xyz>
          <dynamics>
            <damping>0.001</damping>
            <spring_reference>0</spring_reference>
            <spring_stiffness>0</spring_stiffness>
          </dynamics>
          <limit>
            <lower>-1e+16</lower>
            <upper>1e+16</upper>
          </limit>
        </axis>
      </joint>
      <link name='front_left'>
        <pose>-0.04 -0.245 -0.05 0 -0 1.5708</pose>
        <inertial>
          <pose>0 0 0 3.14159 1.57079 3.14159</pose>
          <mass>0.01</mass>
          <inertia>
            <ixx>1.75e-05</ixx>
            <ixy>0</ixy>
            <ixz>0</ixz>
            <iyy>1.75e-05</iyy>
            <iyz>0</iyz>
            <izz>3.125e-05</izz>
          </inertia>
        </inertial>
        <collision name='front_left_collision'>
          <pose>0 0 0 3.14159 1.57079 3.14159</pose>
          <geometry>
            <cylinder>
              <length>0.03</length>
              <radius>0.06</radius>
            </cylinder>
          </geometry>
          <max_contacts>5</max_contacts>
          <surface>
            <contact>
              <ode>
                <soft_cfm>1</soft_cfm>
                <soft_erp>0.4</soft_erp>
                <kp>1e+06</kp>
                <kd>1</kd>
                <min_depth>0.01</min_depth>
              </ode>
            </contact>
            <friction>
              <ode>
                <mu>1.16</mu>
                <mu2>1.16</mu2>
              </ode>
              <torsional>
                <ode/>
              </torsional>
            </friction>
            <bounce/>
          </surface>
        </collision>
        <visual name='front_left_visual'>
          <pose>0 0 0 0 -0 0</pose>
          <geometry>
            <mesh>
              <scale>1 1 1</scale>
              <uri>/home/bambinojr/.ignition/fuel/fuel.ignitionrobotics.org/movai/models/cart_model_2/2/meshes/wheel.dae</uri>
            </mesh>
          </geometry>
        </visual>
        <self_collide>0</self_collide>
        <enable_wind>0</enable_wind>
        <kinematic>0</kinematic>
      </link>
      <joint name='front_left_joint' type='revolute'>
        <child>front_left</child>
        <parent>wheel_sup_front_left</parent>
        <axis>
          <xyz>1 0 0</xyz>
          <dynamics>
            <friction>0.5</friction>
            <damping>0.0001</damping>
            <spring_reference>0</spring_reference>
            <spring_stiffness>0</spring_stiffness>
          </dynamics>
          <limit>
            <lower>-1e+16</lower>
            <upper>1e+16</upper>
          </limit>
        </axis>
      </joint>
      <link name='wheel_sup_front_right'>
        <pose>0 0.245 0.05 0 -0 1.5708</pose>
        <inertial>
          <pose>0 0 0 0 -0 0</pose>
          <mass>0.01</mass>
          <inertia>
            <ixx>1.75e-05</ixx>
            <ixy>0</ixy>
            <ixz>0</ixz>
            <iyy>1.75e-05</iyy>
            <iyz>0</iyz>
            <izz>1.75e-05</izz>
          </inertia>
        </inertial>
        <visual name='wheel_sup_front_right_visual'>
          <pose>0 0 0 0 -0 -3.14159</pose>
          <geometry>
            <mesh>
              <scale>1 1 1</scale>
              <uri>/home/bambinojr/.ignition/fuel/fuel.ignitionrobotics.org/movai/models/cart_model_2/2/meshes/sup_wheels.dae</uri>
            </mesh>
          </geometry>
        </visual>
        <self_collide>0</self_collide>
        <enable_wind>0</enable_wind>
        <kinematic>0</kinematic>
      </link>
      <joint name='wheel_sup_front_right_joint' type='revolute'>
        <child>wheel_sup_front_right</child>
        <parent>base_link</parent>
        <axis>
          <xyz>0 0 1</xyz>
          <dynamics>
            <damping>0.001</damping>
            <spring_reference>0</spring_reference>
            <spring_stiffness>0</spring_stiffness>
          </dynamics>
          <limit>
            <lower>-1e+16</lower>
            <upper>1e+16</upper>
          </limit>
        </axis>
      </joint>
      <link name='front_right'>
        <pose>-0.04 0.245 -0.05 0 -0 1.5708</pose>
        <inertial>
          <pose>0 0 0 3.14159 1.57079 3.14159</pose>
          <mass>0.01</mass>
          <inertia>
            <ixx>1.75e-05</ixx>
            <ixy>0</ixy>
            <ixz>0</ixz>
            <iyy>1.75e-05</iyy>
            <iyz>0</iyz>
            <izz>3.125e-05</izz>
          </inertia>
        </inertial>
        <collision name='front_right_collision'>
          <pose>0 0 0 3.14159 1.57079 3.14159</pose>
          <geometry>
            <cylinder>
              <length>0.03</length>
              <radius>0.06</radius>
            </cylinder>
          </geometry>
          <max_contacts>5</max_contacts>
          <surface>
            <contact>
              <ode>
                <soft_cfm>1</soft_cfm>
                <soft_erp>0.4</soft_erp>
                <kp>1e+06</kp>
                <kd>1</kd>
                <min_depth>0.01</min_depth>
              </ode>
            </contact>
            <friction>
              <ode>
                <mu>1.16</mu>
                <mu2>1.16</mu2>
              </ode>
              <torsional>
                <ode/>
              </torsional>
            </friction>
            <bounce/>
          </surface>
        </collision>
        <visual name='front_right_visual'>
          <pose>0 0 0 0 -0 0</pose>
          <geometry>
            <mesh>
              <scale>1 1 1</scale>
              <uri>/home/bambinojr/.ignition/fuel/fuel.ignitionrobotics.org/movai/models/cart_model_2/2/meshes/wheel.dae</uri>
            </mesh>
          </geometry>
        </visual>
        <self_collide>0</self_collide>
        <enable_wind>0</enable_wind>
        <kinematic>0</kinematic>
      </link>
      <joint name='front_right_joint' type='revolute'>
        <child>front_right</child>
        <parent>wheel_sup_front_right</parent>
        <axis>
          <xyz>1 0 0</xyz>
          <dynamics>
            <friction>0.5</friction>
            <damping>0.0001</damping>
            <spring_reference>0</spring_reference>
            <spring_stiffness>0</spring_stiffness>
          </dynamics>
          <limit>
            <lower>-1e+16</lower>
            <upper>1e+16</upper>
          </limit>
        </axis>
      </joint>
    </model>
    <model name='shelf_big'>
      <pose>5.22075 -0.683437 0 0 -0 0</pose>
      <self_collide>1</self_collide>
      <link name='shelf_big_base'>
        <pose>-0.5 0 0 0 -0 0</pose>
        <collision name='shelf_big_chassi_collision'>
          <pose>0 0 3 0 -0 0</pose>
          <geometry>
            <box>
              <size>2.1 18 6</size>
            </box>
          </geometry>
          <max_contacts>10</max_contacts>
          <surface>
            <contact>
              <ode/>
            </contact>
            <bounce/>
            <friction>
              <torsional>
                <ode/>
              </torsional>
              <ode/>
            </friction>
          </surface>
        </collision>
        <visual name='shelf_big_chassi_visual'>
          <pose>0 0 0 0 -0 1.5708</pose>
          <geometry>
            <mesh>
              <scale>1 1 1</scale>
              <uri>/home/bambinojr/.ignition/fuel/fuel.ignitionrobotics.org/ctrazziwp/models/shelf_big/1/meshes/shelf_big_movai.dae</uri>
            </mesh>
          </geometry>
        </visual>
        <self_collide>1</self_collide>
        <enable_wind>0</enable_wind>
        <kinematic>0</kinematic>
      </link>
      <static>1</static>
    </model>
    <model name='shelf'>
      <pose>-1.81691 3.91662 0 0 -0 0</pose>
      <self_collide>1</self_collide>
      <link name='shelf_base'>
        <pose>-0.5 0 0 0 -0 0</pose>
        <collision name='shelf_chassi_collision'>
          <pose>0 0 0.9 0 -0 0</pose>
          <geometry>
            <box>
              <size>3.6 0.6 1.8</size>
            </box>
          </geometry>
          <max_contacts>10</max_contacts>
          <surface>
            <contact>
              <ode/>
            </contact>
            <bounce/>
            <friction>
              <torsional>
                <ode/>
              </torsional>
              <ode/>
            </friction>
          </surface>
        </collision>
        <visual name='shelf_chassi_visual'>
          <pose>0 0 0 0 -0 0</pose>
          <geometry>
            <mesh>
              <scale>0.2 0.3 0.3</scale>
              <uri>/home/bambinojr/.ignition/fuel/fuel.ignitionrobotics.org/ctrazziwp/models/shelf/1/meshes/shelf_big_movai.dae</uri>
            </mesh>
          </geometry>
        </visual>
        <self_collide>1</self_collide>
        <enable_wind>0</enable_wind>
        <kinematic>0</kinematic>
      </link>
      <static>1</static>
    </model>
    <model name='Construction Cone'>
      <link name='link'>
        <collision name='collision'>
          <geometry>
            <mesh>
              <scale>10 10 10</scale>
              <uri>https://fuel.ignitionrobotics.org/1.0/adlarkin/models/construction cone label test/1/files/meshes/construction_cone.dae</uri>
            </mesh>
          </geometry>
          <max_contacts>10</max_contacts>
          <surface>
            <contact>
              <ode/>
            </contact>
            <bounce/>
            <friction>
              <torsional>
                <ode/>
              </torsional>
              <ode/>
            </friction>
          </surface>
        </collision>
        <visual name='visual'>
          <geometry>
            <mesh>
              <scale>10 10 10</scale>
              <uri>https://fuel.ignitionrobotics.org/1.0/adlarkin/models/construction cone label test/1/files/meshes/construction_cone.dae</uri>
            </mesh>
          </geometry>
        </visual>
        <self_collide>0</self_collide>
        <inertial>
          <pose>0 0 0 0 -0 0</pose>
          <inertia>
            <ixx>1</ixx>
            <ixy>0</ixy>
            <ixz>0</ixz>
            <iyy>1</iyy>
            <iyz>0</iyz>
            <izz>1</izz>
          </inertia>
          <mass>1</mass>
        </inertial>
        <enable_wind>0</enable_wind>
        <kinematic>0</kinematic>
      </link>
      <pose>1.99265 -2.03114 0 0 -0 0</pose>
    </model>
    <model name='Construction Cone_0'>
      <link name='link'>
        <collision name='collision'>
          <geometry>
            <mesh>
              <scale>10 10 10</scale>
              <uri>https://fuel.ignitionrobotics.org/1.0/adlarkin/models/construction cone label test/1/files/meshes/construction_cone.dae</uri>
            </mesh>
          </geometry>
          <max_contacts>10</max_contacts>
          <surface>
            <contact>
              <ode/>
            </contact>
            <bounce/>
            <friction>
              <torsional>
                <ode/>
              </torsional>
              <ode/>
            </friction>
          </surface>
        </collision>
        <visual name='visual'>
          <geometry>
            <mesh>
              <scale>10 10 10</scale>
              <uri>https://fuel.ignitionrobotics.org/1.0/adlarkin/models/construction cone label test/1/files/meshes/construction_cone.dae</uri>
            </mesh>
          </geometry>
        </visual>
        <self_collide>0</self_collide>
        <inertial>
          <pose>0 0 0 0 -0 0</pose>
          <inertia>
            <ixx>1</ixx>
            <ixy>0</ixy>
            <ixz>0</ixz>
            <iyy>1</iyy>
            <iyz>0</iyz>
            <izz>1</izz>
          </inertia>
          <mass>1</mass>
        </inertial>
        <enable_wind>0</enable_wind>
        <kinematic>0</kinematic>
      </link>
      <pose>1.48083 -2.52447 0 0 -0 0</pose>
    </model>
    <model name='Construction Cone_1'>
      <link name='link'>
        <collision name='collision'>
          <geometry>
            <mesh>
              <scale>10 10 10</scale>
              <uri>https://fuel.ignitionrobotics.org/1.0/adlarkin/models/construction cone label test/1/files/meshes/construction_cone.dae</uri>
            </mesh>
          </geometry>
          <max_contacts>10</max_contacts>
          <surface>
            <contact>
              <ode/>
            </contact>
            <bounce/>
            <friction>
              <torsional>
                <ode/>
              </torsional>
              <ode/>
            </friction>
          </surface>
        </collision>
        <visual name='visual'>
          <geometry>
            <mesh>
              <scale>10 10 10</scale>
              <uri>https://fuel.ignitionrobotics.org/1.0/adlarkin/models/construction cone label test/1/files/meshes/construction_cone.dae</uri>
            </mesh>
          </geometry>
        </visual>
        <self_collide>0</self_collide>
        <inertial>
          <pose>0 0 0 0 -0 0</pose>
          <inertia>
            <ixx>1</ixx>
            <ixy>0</ixy>
            <ixz>0</ixz>
            <iyy>1</iyy>
            <iyz>0</iyz>
            <izz>1</izz>
          </inertia>
          <mass>1</mass>
        </inertial>
        <enable_wind>0</enable_wind>
        <kinematic>0</kinematic>
      </link>
      <pose>2.28788 -1.46354 0 0 -0 0</pose>
    </model>
    <model name='Construction Cone_2'>
      <link name='link'>
        <collision name='collision'>
          <geometry>
            <mesh>
              <scale>10 10 10</scale>
              <uri>https://fuel.ignitionrobotics.org/1.0/adlarkin/models/construction cone label test/1/files/meshes/construction_cone.dae</uri>
            </mesh>
          </geometry>
          <max_contacts>10</max_contacts>
          <surface>
            <contact>
              <ode/>
            </contact>
            <bounce/>
            <friction>
              <torsional>
                <ode/>
              </torsional>
              <ode/>
            </friction>
          </surface>
        </collision>
        <visual name='visual'>
          <geometry>
            <mesh>
              <scale>10 10 10</scale>
              <uri>https://fuel.ignitionrobotics.org/1.0/adlarkin/models/construction cone label test/1/files/meshes/construction_cone.dae</uri>
            </mesh>
          </geometry>
        </visual>
        <self_collide>0</self_collide>
        <inertial>
          <pose>0 0 0 0 -0 0</pose>
          <inertia>
            <ixx>1</ixx>
            <ixy>0</ixy>
            <ixz>0</ixz>
            <iyy>1</iyy>
            <iyz>0</iyz>
            <izz>1</izz>
          </inertia>
          <mass>1</mass>
        </inertial>
        <enable_wind>0</enable_wind>
        <kinematic>0</kinematic>
      </link>
      <pose>0.854891 -2.92193 0 0 -0 0</pose>
    </model>
    <model name='Construction Cone_3'>
      <link name='link'>
        <collision name='collision'>
          <geometry>
            <mesh>
              <scale>10 10 10</scale>
              <uri>https://fuel.ignitionrobotics.org/1.0/adlarkin/models/construction cone label test/1/files/meshes/construction_cone.dae</uri>
            </mesh>
          </geometry>
          <max_contacts>10</max_contacts>
          <surface>
            <contact>
              <ode/>
            </contact>
            <bounce/>
            <friction>
              <torsional>
                <ode/>
              </torsional>
              <ode/>
            </friction>
          </surface>
        </collision>
        <visual name='visual'>
          <geometry>
            <mesh>
              <scale>10 10 10</scale>
              <uri>https://fuel.ignitionrobotics.org/1.0/adlarkin/models/construction cone label test/1/files/meshes/construction_cone.dae</uri>
            </mesh>
          </geometry>
        </visual>
        <self_collide>0</self_collide>
        <inertial>
          <pose>0 0 0 0 -0 0</pose>
          <inertia>
            <ixx>1</ixx>
            <ixy>0</ixy>
            <ixz>0</ixz>
            <iyy>1</iyy>
            <iyz>0</iyz>
            <izz>1</izz>
          </inertia>
          <mass>1</mass>
        </inertial>
        <enable_wind>0</enable_wind>
        <kinematic>0</kinematic>
      </link>
      <pose>-4.38508 -1.64143 0 0 -0 0</pose>
    </model>
    <model name='Construction Cone_4'>
      <link name='link'>
        <collision name='collision'>
          <geometry>
            <mesh>
              <scale>10 10 10</scale>
              <uri>https://fuel.ignitionrobotics.org/1.0/adlarkin/models/construction cone label test/1/files/meshes/construction_cone.dae</uri>
            </mesh>
          </geometry>
          <max_contacts>10</max_contacts>
          <surface>
            <contact>
              <ode/>
            </contact>
            <bounce/>
            <friction>
              <torsional>
                <ode/>
              </torsional>
              <ode/>
            </friction>
          </surface>
        </collision>
        <visual name='visual'>
          <geometry>
            <mesh>
              <scale>10 10 10</scale>
              <uri>https://fuel.ignitionrobotics.org/1.0/adlarkin/models/construction cone label test/1/files/meshes/construction_cone.dae</uri>
            </mesh>
          </geometry>
        </visual>
        <self_collide>0</self_collide>
        <inertial>
          <pose>0 0 0 0 -0 0</pose>
          <inertia>
            <ixx>1</ixx>
            <ixy>0</ixy>
            <ixz>0</ixz>
            <iyy>1</iyy>
            <iyz>0</iyz>
            <izz>1</izz>
          </inertia>
          <mass>1</mass>
        </inertial>
        <enable_wind>0</enable_wind>
        <kinematic>0</kinematic>
      </link>
      <pose>-4.86824 -1.18126 0 0 -0 0</pose>
    </model>
    <model name='Construction Cone_5'>
      <link name='link'>
        <collision name='collision'>
          <geometry>
            <mesh>
              <scale>10 10 10</scale>
              <uri>https://fuel.ignitionrobotics.org/1.0/adlarkin/models/construction cone label test/1/files/meshes/construction_cone.dae</uri>
            </mesh>
          </geometry>
          <max_contacts>10</max_contacts>
          <surface>
            <contact>
              <ode/>
            </contact>
            <bounce/>
            <friction>
              <torsional>
                <ode/>
              </torsional>
              <ode/>
            </friction>
          </surface>
        </collision>
        <visual name='visual'>
          <geometry>
            <mesh>
              <scale>10 10 10</scale>
              <uri>https://fuel.ignitionrobotics.org/1.0/adlarkin/models/construction cone label test/1/files/meshes/construction_cone.dae</uri>
            </mesh>
          </geometry>
        </visual>
        <self_collide>0</self_collide>
        <inertial>
          <pose>0 0 0 0 -0 0</pose>
          <inertia>
            <ixx>1</ixx>
            <ixy>0</ixy>
            <ixz>0</ixz>
            <iyy>1</iyy>
            <iyz>0</iyz>
            <izz>1</izz>
          </inertia>
          <mass>1</mass>
        </inertial>
        <enable_wind>0</enable_wind>
        <kinematic>0</kinematic>
      </link>
      <pose>-4.40255 3.32507 0 0 -0 0</pose>
    </model>
    <state world_name='default'>
      <sim_time>600 858000000</sim_time>
      <real_time>604 922837501</real_time>
      <wall_time>1741434698 9126083</wall_time>
      <iterations>600858</iterations>
      <model name='Construction Cone'>
        <pose>1.99265 -2.03114 -1e-05 -1e-06 0 0</pose>
        <scale>1 1 1</scale>
        <link name='link'>
          <pose>1.99265 -2.03114 -1e-05 -1e-06 0 0</pose>
          <velocity>0 0 0 0 -0 0</velocity>
          <acceleration>0 0 -9.8 0 -0 0</acceleration>
          <wrench>0 0 -9.8 0 -0 0</wrench>
        </link>
      </model>
      <model name='Construction Cone_0'>
        <pose>1.48083 -2.52447 -1e-05 0 -0 0</pose>
        <scale>1 1 1</scale>
        <link name='link'>
          <pose>1.48083 -2.52447 -1e-05 0 -0 0</pose>
          <velocity>0 0 0 0 -0 0</velocity>
          <acceleration>0 0 -9.8 0 -0 0</acceleration>
          <wrench>0 0 -9.8 0 -0 0</wrench>
        </link>
      </model>
      <model name='Construction Cone_1'>
        <pose>2.28788 -1.46354 0 -0 -0 -0</pose>
        <scale>1 1 1</scale>
        <link name='link'>
          <pose>2.28788 -1.46354 0 -0 -0 -0</pose>
          <velocity>0 0 0 0 -0 0</velocity>
          <acceleration>-0 -0 19.2417 1.54373 -0.176379 0</acceleration>
          <wrench>-0 -0 19.2417 0 -0 0</wrench>
        </link>
      </model>
      <model name='Construction Cone_2'>
        <pose>0.854891 -2.92193 -1e-05 -1e-06 0 0</pose>
        <scale>1 1 1</scale>
        <link name='link'>
          <pose>0.854891 -2.92193 -1e-05 -1e-06 0 0</pose>
          <velocity>0 0 0 0 -0 0</velocity>
          <acceleration>0 0 -9.8 0 -0 0</acceleration>
          <wrench>0 0 -9.8 0 -0 0</wrench>
        </link>
      </model>
      <model name='Construction Cone_3'>
        <pose>-4.38508 -1.64143 -1e-05 0 -0 0</pose>
        <scale>1 1 1</scale>
        <link name='link'>
          <pose>-4.38508 -1.64143 -1e-05 0 -0 0</pose>
          <velocity>0 0 0 0 -0 0</velocity>
          <acceleration>0 0 -9.8 0 -0 0</acceleration>
          <wrench>0 0 -9.8 0 -0 0</wrench>
        </link>
      </model>
      <model name='Construction Cone_4'>
        <pose>-4.86824 -1.18126 -0 0 -0 0</pose>
        <scale>1 1 1</scale>
        <link name='link'>
          <pose>-4.86824 -1.18126 -0 0 -0 0</pose>
          <velocity>0 0 0 0 -0 0</velocity>
          <acceleration>0 -0 -0.008512 -2.58585 1.13682 3.14159</acceleration>
          <wrench>0 -0 -0.008512 0 -0 0</wrench>
        </link>
      </model>
      <model name='Construction Cone_5'>
        <pose>-4.40255 3.32507 -0 0 -1e-06 0</pose>
        <scale>1 1 1</scale>
        <link name='link'>
          <pose>-4.40255 3.32507 -0 0 -1e-06 0</pose>
          <velocity>0 0 0 0 -0 0</velocity>
          <acceleration>-0 0 0.008512 2.58585 -1.13682 -3.14159</acceleration>
          <wrench>-0 0 0.008512 0 -0 0</wrench>
        </link>
      </model>
      <model name='cart_model2'>
        <pose>2.69347 2.55326 0.098969 0.000282 0.000637 1.32373</pose>
        <scale>1 1 1</scale>
        <link name='back_left'>
          <pose>2.67669 1.48492 0.050013 -1.99841 0.001218 2.89456</pose>
          <velocity>-0.001136 -0.003774 0.000288 0.063667 -0.019016 -0.018608</velocity>
          <acceleration>-7.1e-05 1.9e-05 0 0.003931 0.039507 -0.000462</acceleration>
          <wrench>-1e-06 0 0 0 -0 0</wrench>
        </link>
        <link name='back_right'>
          <pose>2.20157 1.60473 0.050009 1.82369 0.000951 2.89462</pose>
          <velocity>0.00113 0.005068 0.000223 -0.083598 0.018695 -0.018732</velocity>
          <acceleration>0.000106 3e-05 -0 -0.005995 -0.050754 0.000242</acceleration>
          <wrench>1e-06 0 -0 0 -0 0</wrench>
        </link>
        <link name='base_link'>
          <pose>2.69347 2.55326 0.098969 -0.000637 0.000282 -0.247073</pose>
          <velocity>0.018889 -0.00415 -4.8e-05 -9.6e-05 7.8e-05 -0.018693</velocity>
          <acceleration>3.1e-05 -0.000173 0 2e-06 2e-06 -0.000113</acceleration>
          <wrench>0.000926 -0.005197 0 0 -0 0</wrench>
        </link>
        <link name='front_left'>
          <pose>2.89435 2.50929 0.050014 0.935445 0.001513 1.16085</pose>
          <velocity>0.018295 -0.007691 0.000322 0.127491 0.303633 -0.021159</velocity>
          <acceleration>-3.1e-05 -0.000369 0 0.129894 -0.474359 0.001811</acceleration>
          <wrench>-0 -4e-06 0 0 -0 0</wrench>
        </link>
        <link name='front_right'>
          <pose>2.41638 2.61113 0.050034 -1.91616 0.002824 1.62195</pose>
          <velocity>0.020006 0.001302 0.000297 -0.02166 0.332515 -0.02093</velocity>
          <acceleration>0.000149 -0.000347 -0 -0.009612 -0.469276 0.002517</acceleration>
          <wrench>1e-06 -3e-06 -0 0 -0 0</wrench>
        </link>
        <link name='wheel_sup_front_left'>
          <pose>2.93101 2.4934 0.149345 0.014512 0.001271 1.16064</pose>
          <velocity>0.01778 -0.008572 0.000105 -0.000982 0.003807 -0.022204</velocity>
          <acceleration>-4.7e-05 -0.00036 -0 6.8e-05 2.1e-05 -2.6e-05</acceleration>
          <wrench>-0 -4e-06 -0 0 -0 0</wrench>
        </link>
        <link name='wheel_sup_front_right'>
          <pose>2.45593 2.6132 0.148919 -0.002129 9e-05 1.62188</pose>
          <velocity>0.020015 0.000294 -6.8e-05 0.000772 -0.000855 -0.021302</velocity>
          <acceleration>0.000131 -0.000348 0 -1.4e-05 -1.3e-05 -1.7e-05</acceleration>
          <wrench>1e-06 -3e-06 0 0 -0 0</wrench>
        </link>
      </model>
      <model name='first_2015_trash_can'>
        <pose>-2.36437 0.298308 -4e-06 -3e-06 5e-06 -0.001521</pose>
        <scale>1 1 1</scale>
        <link name='link'>
          <pose>-2.36437 0.298308 -4e-06 -3e-06 5e-06 -0.001521</pose>
          <velocity>0 0 0 0 -0 0</velocity>
          <acceleration>-1.79618 0.262032 -5.42233 -0.711429 1.40626 1.2e-05</acceleration>
          <wrench>-8.67694 1.26581 -26.194 0 -0 0</wrench>
        </link>
      </model>
      <model name='first_2015_trash_can_0'>
        <pose>-2.32416 2.34429 -2e-06 -5e-06 -1.4e-05 -0.001153</pose>
        <scale>1 1 1</scale>
        <link name='link'>
          <pose>-2.32416 2.34429 -2e-06 -5e-06 -1.4e-05 -0.001153</pose>
          <velocity>0 0 0 0 -0 0</velocity>
          <acceleration>3.06051 -0.428057 -2.46152 -1.83123 0.975724 3.02203</acceleration>
          <wrench>14.7846 -2.06784 -11.891 0 -0 0</wrench>
        </link>
      </model>
      <model name='first_2015_trash_can_1'>
        <pose>-2.31357 -0.495604 -1e-06 4e-06 1.5e-05 -0.001376</pose>
        <scale>1 1 1</scale>
        <link name='link'>
          <pose>-2.31357 -0.495604 -1e-06 4e-06 1.5e-05 -0.001376</pose>
          <velocity>0 0 0 0 -0 0</velocity>
          <acceleration>-5.88497 2.72261 5.8293 2.03234 0.270908 3.14151</acceleration>
          <wrench>-28.4289 13.1523 28.1599 0 -0 0</wrench>
        </link>
      </model>
      <model name='grey_wall'>
        <pose>-0.375864 4.47125 0 0 -0 0</pose>
        <scale>1 1 1</scale>
        <link name='link'>
          <pose>-0.375864 4.47125 1.4 0 -0 0</pose>
          <velocity>0 0 0 0 -0 0</velocity>
          <acceleration>0 0 0 0 -0 0</acceleration>
          <wrench>0 0 0 0 -0 0</wrench>
        </link>
      </model>
      <model name='grey_wall_0'>
        <pose>-0.482636 -4.28038 0 0 -0 0</pose>
        <scale>1 1 1</scale>
        <link name='link'>
          <pose>-0.482636 -4.28038 1.4 0 -0 0</pose>
          <velocity>0 0 0 0 -0 0</velocity>
          <acceleration>0 0 0 0 -0 0</acceleration>
          <wrench>0 0 0 0 -0 0</wrench>
        </link>
      </model>
      <model name='ground_plane'>
        <pose>0 0 0 0 -0 0</pose>
        <scale>1 1 1</scale>
        <link name='link'>
          <pose>0 0 0 0 -0 0</pose>
          <velocity>0 0 0 0 -0 0</velocity>
          <acceleration>0 0 0 0 -0 0</acceleration>
          <wrench>0 0 0 0 -0 0</wrench>
        </link>
      </model>
      <model name='shelf'>
        <pose>-1.81691 3.91662 0 0 -0 0</pose>
        <scale>1 1 1</scale>
        <link name='shelf_base'>
          <pose>-2.31691 3.91662 0 0 -0 0</pose>
          <velocity>0 0 0 0 -0 0</velocity>
          <acceleration>0 0 0 0 -0 0</acceleration>
          <wrench>0 0 0 0 -0 0</wrench>
        </link>
      </model>
      <model name='shelf_big'>
        <pose>5.22075 -0.683437 0 0 -0 0</pose>
        <scale>1 1 1</scale>
        <link name='shelf_big_base'>
          <pose>4.72075 -0.683437 0 0 -0 0</pose>
          <velocity>0 0 0 0 -0 0</velocity>
          <acceleration>0 0 0 0 -0 0</acceleration>
          <wrench>0 0 0 0 -0 0</wrench>
        </link>
      </model>
      <light name='sun'>
        <pose>0 0 10 0 -0 0</pose>
      </light>
    </state>
    <gui fullscreen='0'>
      <camera name='user_camera'>
        <pose>-25.3325 -0.949099 13.1792 0 0.387643 0.192195</pose>
        <view_controller>orbit</view_controller>
        <projection_type>perspective</projection_type>
      </camera>
    </gui>
  </world>
</sdf>
